<robot name="arm">
    <material name="silver">
        <color rgba="0.75 0.75 0.75 1"/>
    </material>

    <link name="world"/>

    <link name="base_link">
        <inertial>
            <mass value="2.0"/>
            <origin rpy="0 0 0" xyz="0 0 0.025"/>
            <inertia ixx="0.01" iyy="0.01" izz="0.015" ixy="0" ixz="0" iyz="0"/>
        </inertial>
        <visual>
            <geometry>
                <cylinder length="0.05" radius="0.1"/>
            </geometry>
            <material name="silver"/>
            <origin rpy="0 0 0" xyz="0 0 0.025"/>
        </visual>
        <collision>
            <geometry>
                <cylinder length="0.05" radius="0.1"/>
            </geometry>
            <origin rpy="0 0 0" xyz="0 0 0.025"/>
        </collision>
    </link>

    <joint name="fixed" type="fixed">
        <parent link="world"/>
        <child link="base_link"/>
    </joint>

    <link name="torso">
        <inertial>
            <mass value="1.5"/>
            <origin rpy="0 0 0" xyz="0 0 0"/>
            <inertia ixx="0.03" iyy="0.03" izz="0.02" ixy="0" ixz="0" iyz="0"/>
        </inertial>
        <visual>
            <geometry>
                <cylinder length="0.12" radius="0.03"/>
            </geometry>
            <material name="silver"/>
            <origin rpy="0 0 0" xyz="0 0 0"/>
        </visual>
        <collision>
            <geometry>
                <cylinder length="0.12" radius="0.03"/>
            </geometry>
            <origin rpy="0 0 0" xyz="0 0 0"/>
        </collision>
    </link>

    <joint name="hip" type="revolute">
        <axis xyz="0 0 1"/>
        <limit velocity="0.5" effort="20.0" upper="1.5708" lower="-1.5708"/>
        <dynamics damping="0.3" friction="0.5"/>
        <parent link="base_link"/>
        <child link="torso"/>
        <origin rpy="0 0 0" xyz="0 0 0.11"/>
    </joint>

    <link name="upper_arm">
        <inertial>
            <mass value="1.5"/>
            <origin rpy="0 0 0" xyz="0 -0.06 0.07"/>
            <inertia ixx="0.025" iyy="0.025" izz="0.02" ixy="0" ixz="0" iyz="0"/>
        </inertial>
        <visual>
            <geometry>
                <cylinder length="0.3" radius="0.03"/>
            </geometry>
            <material name="silver"/>
            <origin rpy="0 0 0" xyz="0 -0.06 0.09"/>
        </visual>
        <collision>
            <geometry>
                <cylinder length="0.3" radius="0.03"/>
            </geometry>
            <origin rpy="0 0 0" xyz="0 -0.06 0.09"/>
        </collision>
    </link>

    <link name="sambungan1">
        <inertial>
            <mass value="2.0"/>
            <origin rpy="0 0 0" xyz="0 0 0.025"/>
            <inertia ixx="0.01" iyy="0.01" izz="0.015" ixy="0" ixz="0" iyz="0"/>
        </inertial>
        <visual>
            <geometry>
                <sphere radius="0.06"/>
            </geometry>
            <material name="silver"/>
            <origin rpy="0 0 0" xyz="0 0 0.05"/>
        </visual>
        <collision>
            <geometry>
                <sphere radius="0.06"/>
            </geometry>
            <origin rpy="0 0 0" xyz="0 0 0.05"/>
        </collision>
    </link>

    <joint name="fixed_sambungan1" type="fixed">
        <parent link="torso"/>
        <child link="sambungan1"/>
    </joint>

    <joint name="shoulder" type="revolute">
        <axis xyz="0 1 0"/>
        <limit velocity="0.5" effort="20.0" upper="0.6981" lower="-1.5708"/>
        <dynamics damping="0.3" friction="0.5"/>
        <parent link="sambungan1"/>
        <child link="upper_arm"/>
        <origin rpy="0 1.5708 0" xyz="0 0.06 0.06"/>
    </joint>

    <link name="forearm">
        <inertial>
            <mass value="1.2"/>
            <origin rpy="0 0 0" xyz="0 -0.005 0.12"/>
            <inertia ixx="0.02" iyy="0.02" izz="0.015" ixy="0" ixz="0" iyz="0"/>
        </inertial>
        <visual>
            <geometry>
                <cylinder length="0.3" radius="0.03"/>
            </geometry>
            <material name="silver"/>
            <origin rpy="0 0 0" xyz="0 -0.005 0.12"/>
        </visual>
        <collision>
            <geometry>
                <cylinder length="0.3" radius="0.03"/>
            </geometry>
            <origin rpy="0 0 0" xyz="0 -0.005 0.12"/>
        </collision>
    </link>

    <link name="sambungan2">
        <inertial>
            <mass value="2.0"/>
            <origin rpy="0 0 0" xyz="0 0 0.025"/>
            <inertia ixx="0.01" iyy="0.01" izz="0.015" ixy="0" ixz="0" iyz="0"/>
        </inertial>
        <visual>
            <geometry>
                <sphere radius="0.06"/>
            </geometry>
            <material name="silver"/>
            <origin rpy="0 0 0" xyz="0 -0.06 0.2"/>
        </visual>
        <collision>
            <geometry>
                <sphere radius="0.06"/>
            </geometry>
            <origin rpy="0 0 0" xyz="0 -0.06 0.2"/>
        </collision>
    </link>

    <joint name="fixed_sambungan2" type="fixed">
        <parent link="upper_arm"/>
        <child link="sambungan2"/>
    </joint>

    <joint name="elbow" type="revolute">
        <axis xyz="0 1 0"/>
        <limit velocity="0.5" effort="20.0" upper="1.5708" lower="-1.5708"/>
        <dynamics damping="0.3" friction="0.5"/>
        <parent link="sambungan2"/>
        <child link="forearm"/>
        <origin rpy="0 0 0" xyz="0 -0.055 0.2"/>
    </joint>

    <link name="hand">
        <inertial>
            <mass value="1.2"/>
            <origin rpy="0 0 0" xyz="0 0 0.15"/>
            <inertia ixx="0.02" iyy="0.02" izz="0.015" ixy="0" ixz="0" iyz="0"/>
        </inertial>
        <visual>
            <geometry>
                <cylinder length="0.3" radius="0.03"/>
            </geometry>
            <material name="silver"/>
            <origin rpy="0 0 0" xyz="0.0 0.05 0.15"/>
        </visual>
        <collision>
            <geometry>
                <cylinder length="0.3" radius="0.03"/>
            </geometry>
            <origin rpy="0 0 0" xyz="0 0.05 0.15"/>
        </collision>
    </link>

    <link name="sambungan3">
        <inertial>
            <mass value="2.0"/>
            <origin rpy="0 0 0" xyz="0 0 0.025"/>
            <inertia ixx="0.01" iyy="0.01" izz="0.015" ixy="0" ixz="0" iyz="0"/>
        </inertial>
        <visual>
            <geometry>
                <sphere radius="0.06"/>
            </geometry>
            <material name="silver"/>
            <origin rpy="0 0 0" xyz="0 0 0.2"/>
        </visual>
        <collision>
            <geometry>
                <sphere radius="0.06"/>
            </geometry>
            <origin rpy="0 0 0" xyz="0 0 0.2"/>
        </collision>
    </link>

    <joint name="fixed_sambungan3" type="fixed">
        <parent link="forearm"/>
        <child link="sambungan3"/>
    </joint>

    <joint name="gelang" type="revolute">
        <axis xyz="0 1 0"/>
        <limit velocity="0.5" effort="20.0" upper="1.5708" lower="-1.5708"/>
        <dynamics damping="0.3" friction="0.5"/>
        <parent link="sambungan3"/>
        <child link="hand"/>
        <origin rpy="0 0 0" xyz="0 -0.055 0.2"/>
    </joint>

    <link name="pensil">
        <inertial>
            <mass value="0.5"/>
            <origin rpy="0 0 0" xyz="0 0 0.15"/>
            <inertia ixx="0.01" iyy="0.01" izz="0.005" ixy="0" ixz="0" iyz="0"/>
        </inertial>
        <visual>
            <geometry>
                <cylinder length="0.3" radius="0.01"/>
            </geometry>
            <origin rpy="0 0 0" xyz="0 0.05 0.15"/>
        </visual>
        <collision>
            <geometry>
                <cylinder length="0.3" radius="0.01"/>
            </geometry>
            <origin rpy="0 0 0" xyz="0 0.05 0.15"/>
        </collision>
    </link>

    <joint name="tulis" type="prismatic">
        <parent link="hand"/>
        <child link="pensil"/>
        <axis xyz="0 0 1"/>
        <limit effort="1000.0" lower="-0.1" upper="0.1" velocity="0.5"/>
        <origin rpy="0 0 0" xyz="0 0 0.15"/>
    </joint>
</robot>
